Workbook
Name année: 'Amort Beneduc'!$D$193:$D$209
Name mois: 'Amort Beneduc'!$C$7:$C$18

Sheet Vision patrimoine
B2: SCI IR BENEDUC
B4: Mois | C4: Année | D4: {=MATCH(1,('Amort Beneduc'!$C$5:$C$191=$B$5)*('Amort Beneduc'!$D$5:$D$191=$C$5),0)} -> 41 | L4: Part JF crédit 50% | M4: Mensualités JF
B5: Mars | C5: 2026 | L5: =F14/2 -> 80048.115 | M5: =H14/2 -> 926.085
B7: Adresse | C7: Type de bien | D7: Nombre d'appartement | E7: Credit Résiduel | F7: Credit Résiduel | G7: Loyer mens HC | H7: Montant mensualité | I7: Cash mensuel | J7: Loyer ann HC | K7: Taxe Fonciere | L7: Fin de credit | M7: Valeur de revente
B8: 22 RUE SERY 13003 | C8: TYPE 2/3 | D8: 1 | E8: 42620.35 | F8: {=INDEX('Amort Beneduc'!$E$5:$I$191,MATCH(1,('Amort Beneduc'!$C$5:$C$191=$B$5)*('Amort Beneduc'!$D$5:$D$191=$C$5),0),1)} -> 25013.15 | G8: 534 | H8: 440.18 | I8: =G8-H8-(K8/12) -> 59.653333 | J8: =(G8*12) -> 6408 | K8: 410 | L8: 11444 | M8: 85000
B9: 47 RUE DANTON RDC 13003 | C9: TYPE 2/3 | D9: 2 | E9: 33327.18 | G9: 450 | H9: 175 | I9: =G9-H9-(K9/12) -> 251.25 | J9: =(G9*12) -> 5400 | K9: 285 | L9: 11475 | M9: 60000
B10: 47 RUE DANTON 1er 13003 | C10: TYPE 2+TERRASSE | F10: {=INDEX('Amort Beneduc'!$E$5:$I$191,MATCH(1,('Amort Beneduc'!$C$5:$C$191=$B$5)*('Amort Beneduc'!$D$5:$D$191=$C$5),0),2)} -> 19327.18 | G10: 450 | H10: 175 | I10: =G10-H10-(K10/12) -> 251.25 | J10: =(G10*12) -> 5400 | K10: 285
B11: 4 RUE MIREILLE 13400 | C11: TYPE 2 | D11: 1 | E11: 59906.01 | F11: {=INDEX('Amort Beneduc'!$E$5:$I$191,MATCH(1,('Amort Beneduc'!$C$5:$C$191=$B$5)*('Amort Beneduc'!$D$5:$D$191=$C$5),0),4)} -> 42598.01 | G11: 566 | H11: 432.7 | I11: =G11-H11-(K11/12) -> 89.133333 | J11: =(G11*12) -> 6792 | K11: 530 | L11: Fev-35 | M11: 85000
B12: 25 BD NOTRE DAME 13006 | C12: TYPE 1+TERRASSE | D12: 1 | E12: 98329.49 | F12: {=INDEX('Amort Beneduc'!$E$5:$I$191,MATCH(1,('Amort Beneduc'!$C$5:$C$191=$B$5)*('Amort Beneduc'!$D$5:$D$191=$C$5),0),5)} -> 73157.89 | G12: 540 | H12: 629.29 | I12: =G12-H12-(K12/12) -> -147.62333 | J12: =(G12*12) -> 6480 | K12: 700 | L12: Fev-38 | M12: 150000
B13: 221 BD LIBERATION 13004 | C13: TYPE 1 | D13: 1 | E13: 68990 | F13: {=INDEX('Amort Beneduc'!$E$5:$I$191,MATCH(1,('Amort Beneduc'!$C$5:$C$191=$B$5)*('Amort Beneduc'!$D$5:$D$191=$C$5),0),3)} -> 68990 | G13: 425 | H13: 590.28 | I13: =G13-H13-(K13/12) -> -206.53 | J13: =(G13*12) -> 5100 | K13: 495 | L13: Fev-38 | M13: 115000
B14: TOTAL | E14: =SUM(E8:E12) -> 234183.03 | F14: =SUM(F8:F12) -> 160096.23 | G14: =SUM(G8:G12) -> 2540 | H14: =SUM(H8:H12) -> 1852.17 | I14: =SUM(I8:I12) -> 503.66333 | J14: =SUM(J8:J12) -> 30480 | K14: =SUM(K8:K12) -> 2210 | M14: =SUM(M8:M12) -> 380000
B16: SCI IR TROIKA
B18: Mois | C18: Année | D18: {=MATCH(1,('Amort Troika'!$B$5:$B$146='Vision patrimoine'!$B$19)*('Amort Troika'!$C$5:$C$146='Vision patrimoine'!$C$19),0)} -> 36 | L18: Part JF crédit 33% | M18: Mensualités JF
B19: Octobre | C19: 2025 | L19: =F26/3 -> 126275.74 | M19: =H26/3 -> 1660.0133
B21: Adresse | C21: type de bien | D21: Nombre d'appartement | E21: Credit Résiduel | F21: Credit Résiduel | G21: loyer men HC | H21: Montant mensualité | I21: Cash mensuel | J21: Loyer ann HC | K21: Taxe Fonciere | L21: Fin de credit | M21: Valeur de revente
B22: 23 RUE ROGER SCHIAFFINI 13003 | C22: IMMEUBLE 8LOTS | D22: 8 | E22: 332569 | F22: {=INDEX('Amort Troika'!$D$5:$H$146,MATCH(1,('Amort Troika'!$B$5:$B$146='Vision patrimoine'!$B$19)*('Amort Troika'!$C$5:$C$146='Vision patrimoine'!$C$19),0),1)} -> 216717.25 | G22: 5035 | H22: 3310.05 | I22: =G22-H22-(K22)/12 -> 1508.2833 | J22: =G22*12 -> 60420 | K22: 2600 | L22: 11567 | M22: 670000
B23: 23 RUE ANTOINE MAILLE 13005 | C23: T2 + Terrasse | D23: 1 | E23: 103262.68 | F23: {=INDEX('Amort Troika'!$D$5:$H$146,MATCH(1,('Amort Troika'!$B$5:$B$146='Vision patrimoine'!$B$19)*('Amort Troika'!$C$5:$C$146='Vision patrimoine'!$C$19),0),3)} -> 73353.43 | G23: 740 | H23: 854.55 | I23: =G23-H23-(K23)/12 -> -184.13333 | J23: =G23*12 -> 8880 | K23: 835 | L23: 13271 | M23: 145000
B24: 13 RUE ROUSSEL DORIA 13004 | C24: 2 T2 et 1 T1 | D24: 3 | E24: 76008 | F24: {=INDEX('Amort Troika'!$D$5:$H$146,MATCH(1,('Amort Troika'!$B$5:$B$146='Vision patrimoine'!$B$19)*('Amort Troika'!$C$5:$C$146='Vision patrimoine'!$C$19),0),4)} -> 57528 | G24: 1993 | H24: 528 | I24: =G24-H24-(K24)/12 -> 1348.3333 | J24: =G24*12 -> 23916 | K24: 1400 | L24: 13028 | M24: 360000
B25: 13 RUE ROGER SCHIAFFINI 13003 | C25: TYPE 2/3 | D25: 1 | E25: 41288.94 | F25: {=INDEX('Amort Troika'!$D$5:$H$146,MATCH(1,('Amort Troika'!$B$5:$B$146='Vision patrimoine'!$B$19)*('Amort Troika'!$C$5:$C$146='Vision patrimoine'!$C$19),0),5)} -> 31228.54 | H25: 287.44 | I25: =G25-H25-(K25)/12 -> -311.60667 | J25: =G25*12 -> 0 | K25: 290 | L25: 13058 | M25: 90000
B26: Total | E26: =SUM(E22:E25) -> 553128.62 | F26: =SUM(F22:F25) -> 378827.22 | G26: =SUM(G22:G25) -> 7768 | H26: =SUM(H22:H25) -> 4980.04 | I26: =SUM(I22:I25) -> 2360.8767 | J26: =SUM(J22:J25) -> 93216 | K26: =SUM(K22:K25) -> 5125 | M26: =SUM(M22:M25) -> 1265000
B28: SCI IS LA VISTA
B30: Mois | C30: Année | D30: {=MATCH(1,('Amort SCI La vista'!$B$5:$B$148='Vision patrimoine'!$B$31)*('Amort SCI La vista'!$C$5:$C$148='Vision patrimoine'!$C$31),0)} -> 30 | L30: Part JF crédit 33% | M30: Mensualités JF
B31: Octobre | C31: 2025 | D31: 30 | L31: =F36/3 -> 55241.498 | M31: =H36/3 -> 597.99667
B33: Adresse | C33: type de bien | D33: Nombre de locaux | E33: Credit Résiduel | F33: Credit Résiduel | G33: loyer men HC | H33: Montant mensualité | I33: Cash mensuel | J33: Loyer ann HC | K33: Taxe Fonciere | L33: Fin de credit | M33: Valeur de revente
B34: Maison Mathieu | C34: Local professionnel | D34: 1 | E34: 95000 | F34: {=INDEX('Amort SCI La vista'!D5:D148,MATCH(1,('Amort SCI La vista'!$B$5:$B$148='Vision patrimoine'!$B$31)*('Amort SCI La vista'!$C$5:$C$148='Vision patrimoine'!$C$31),0),1)} -> 79463.685 | G34: 1198.8 | H34: 877 | I34: =G34-H34-(K34)/12 -> 175.96667 | J34: =G34*12 -> 14385.6 | K34: 1750 | L34: 49400 | M34: 230000
B35: 221 bd de la libération | C35: Local commercial | D35: 1 | E35: 90000 | F35: {=INDEX('Amort SCI La vista'!F27:F158,MATCH(1,('Amort SCI La vista'!$B$27:$B$158='Vision patrimoine'!$B$31)*('Amort SCI La vista'!$C$27:$C$158='Vision patrimoine'!$C$31),0),1)} -> 86260.81 | G35: 1000 | H35: 916.99 | I35: =G35-H35-(K35)/12 -> 83.01 | J35: =G35*12 -> 12000 | K35: 0 | L35: 49618 | M35: 160000
B36: Total | E36: =SUM(E30:E34) -> 95000 | F36: =SUM(F34:F35) -> 165724.49 | G36: =SUM(G34:G35) -> 2198.8 | H36: =SUM(H34:H35) -> 1793.99 | I36: =SUM(I34:I35) -> 258.97667 | J36: =SUM(J34:J35) -> 26385.6 | K36: =SUM(K34:K35) -> 1750 | M36: =SUM(M34:M35) -> 390000
B38: Residence principale
B40: Mois | C40: Année | D40: {=MATCH(1,('Residence Principale'!$B$5:$B$300='Vision patrimoine'!$B$41)*('Residence Principale'!$C$5:$C$300='Vision patrimoine'!$C$41),0)} -> 12 | J40: Part crédit Johann Faraut 66% | K40: Part crédit Alexandre Niel 34% | L40: Mensualités JF | M40: Mensualités AN
B41: Octobre | C41: 2025 | D41: 12 | J41: =F45*0.66 -> 176038.78 | K41: =F45*0.34 -> 90686.643 | L41: =G44*0.66 -> 554.4 | M41: =G44*0.34 -> 285.6
B43: Adresse | C43: type de bien | D43: Nombre de biens | E43: Credit Résiduel | F43: Capital restant dû (€) | G43: Mensualité hors assurance | H43: Intérêts (€) | I43: Capital remboursé | J43: Autres frais inclus | K43: Taxe Fonciere | L43: Fin de credit | M43: Valeur de revente
B44: 33 chemin du petit pin vert | C44: Maison 140m2 | D44: 1 | E44: ='Residence Principale'!D5 -> 266771.42 | F44: {=INDEX('Residence Principale'!$D$5:$D$300,MATCH(1,('Residence Principale'!$B$5:$B300='Vision patrimoine'!$B$41)*('Residence Principale'!$C$5:$C$300='Vision patrimoine'!$C$41),0),1)} -> 266725.42 | G44: {=INDEX('Residence Principale'!$F$5:$F$300,MATCH(1,('Residence Principale'!$B$5:$B300='Vision patrimoine'!$B$41)*('Residence Principale'!$C$5:$C$300='Vision patrimoine'!$C$41),0),1)} -> 840 | H44: {=INDEX('Residence Principale'!$G$5:$G$300,MATCH(1,('Residence Principale'!$B$5:$B300='Vision patrimoine'!$B$41)*('Residence Principale'!$C$5:$C$300='Vision patrimoine'!$C$41),0),1)} -> 835.75 | I44: {=INDEX('Residence Principale'!$E$5:$E$300,MATCH(1,('Residence Principale'!$B$5:$B300='Vision patrimoine'!$B$41)*('Residence Principale'!$C$5:$C$300='Vision patrimoine'!$C$41),0),1)} -> 4.25 | J44: {=INDEX('Residence Principale'!$H$5:$H$300,MATCH(1,('Residence Principale'!$B$5:$B300='Vision patrimoine'!$B$41)*('Residence Principale'!$C$5:$C$300='Vision patrimoine'!$C$41),0),1)} -> 64.48 | K44: 2400 | L44: 54697 | M44: 630000
B45: Total | E45: =SUM(E40:E44) -> 266771.42 | F45: =SUM(F44) -> 266725.42 | G45: =SUM(G44) -> 840 | H45: =SUM(H44) -> 835.75 | I45: =SUM(I44) -> 4.25 | J45: =SUM(J44) -> 64.48 | K45: =SUM(K44) -> 2400 | M45: =SUM(M44) -> 630000

Sheet Amort Beneduc
C2: Amortissement BENEDUC
C4: Mois | D4: Année | E4: 22 RUE SERY 13003 | F4: 47 RUE DANTON 13003 | G4: 221 Bd libération | H4: 4 RUE MIREILLE 13400 | I4: 25 BD NOTRE DAME 13006
C5: Novembre | D5: 2022 | E5: ='Vision patrimoine'!$E8 -> 42620.35 | F5: ='Vision patrimoine'!$E9 -> 33327.18 | H5: ='Vision patrimoine'!E11 -> 59906.01 | I5: ='Vision patrimoine'!E12 -> 98329.49
C6: Décembre | D6: 2022 | E6: =E5-'Vision patrimoine'!$H$8 -> 42180.17 | F6: =F5-('Vision patrimoine'!$H$9+'Vision patrimoine'!$H$10) -> 32977.18 | H6: =H5-'Vision patrimoine'!$H$11 -> 59473.31 | I6: =I5-'Vision patrimoine'!$H$12 -> 97700.2
C7: Janvier | D7: 2023 | E7: =E6-'Vision patrimoine'!$H$8 -> 41739.99 | F7: =F6-('Vision patrimoine'!$H$9+'Vision patrimoine'!$H$10) -> 32627.18 | H7: =H6-'Vision patrimoine'!$H$11 -> 59040.61 | I7: =I6-'Vision patrimoine'!$H$12 -> 97070.91
C8: Février | D8: 2023 | E8: =E7-'Vision patrimoine'!$H$8 -> 41299.81 | F8: =F7-('Vision patrimoine'!$H$9+'Vision patrimoine'!$H$10) -> 32277.18 | H8: =H7-'Vision patrimoine'!$H$11 -> 58607.91 | I8: =I7-'Vision patrimoine'!$H$12 -> 96441.62 | K8: Mai
C9: Mars | D9: 2023 | E9: =E8-'Vision patrimoine'!$H$8 -> 40859.63 | F9: =F8-('Vision patrimoine'!$H$9+'Vision patrimoine'!$H$10) -> 31927.18 | H9: =H8-'Vision patrimoine'!$H$11 -> 58175.21 | I9: =I8-'Vision patrimoine'!$H$12 -> 95812.33 | K9: 2029
C10: Avril | D10: 2023 | E10: =E9-'Vision patrimoine'!$H$8 -> 40419.45 | F10: =F9-('Vision patrimoine'!$H$9+'Vision patrimoine'!$H$10) -> 31577.18 | H10: =H9-'Vision patrimoine'!$H$11 -> 57742.51 | I10: =I9-'Vision patrimoine'!$H$12 -> 95183.04 | K10: 22 RUE SERY 13003 | L10: 74 RUE MONTE-CRISTO 13004 | M10: 47 RUE DANTON 13003 | N10: 83 BD ODDO 13015 | O10: 4 RUE MIREILLE 13400 | P10: 25 BD NOTRE DAME 13006
C11: Mai | D11: 2023 | E11: =E10-'Vision patrimoine'!$H$8 -> 39979.27 | F11: =F10-('Vision patrimoine'!$H$9+'Vision patrimoine'!$H$10) -> 31227.18 | H11: =H10-'Vision patrimoine'!$H$11 -> 57309.81 | I11: =I10-'Vision patrimoine'!$H$12 -> 94553.75 | K11: {=INDEX($E$5:$I$191,MATCH(1,($C$5:$C$191=$K$8)*($D$5:$D$191=$K$9),0),1)} -> 8286.31 | L11: {=INDEX($E$5:$I$191,MATCH(1,($C$5:$C$191=$K$8)*($D$5:$D$191=$K$9),0),2)} -> 6027.18 | M11: {=INDEX($E$5:$I$191,MATCH(1,($C$5:$C$191=$K$8)*($D$5:$D$191=$K$9),0),3)} -> 53348.18 | N11: {=INDEX($E$5:$I$191,MATCH(1,($C$5:$C$191=$K$8)*($D$5:$D$191=$K$9),0),4)} -> 26155.41 | O11: {=INDEX($E$5:$I$191,MATCH(1,($C$5:$C$191=$K$8)*($D$5:$D$191=$K$9),0),5)} -> 49244.87 | P11: {=INDEX($E$5:$I$191,MATCH(1,($C$5:$C$191=$K$8)*($D$5:$D$191=$K$9),0),6)} -> #REF!
C12: Juin | D12: 2023 | E12: =E11-'Vision patrimoine'!$H$8 -> 39539.09 | F12: =F11-('Vision patrimoine'!$H$9+'Vision patrimoine'!$H$10) -> 30877.18 | H12: =H11-'Vision patrimoine'!$H$11 -> 56877.11 | I12: =I11-'Vision patrimoine'!$H$12 -> 93924.46
C13: Juillet | D13: 2023 | E13: =E12-'Vision patrimoine'!$H$8 -> 39098.91 | F13: =F12-('Vision patrimoine'!$H$9+'Vision patrimoine'!$H$10) -> 30527.18 | H13: =H12-'Vision patrimoine'!$H$11 -> 56444.41 | I13: =I12-'Vision patrimoine'!$H$12 -> 93295.17 | K13: {=MATCH(1,($C$5:$C$191=$K$8)*($D$5:$D$191=$K$9),0)} -> 79
C14: Août | D14: 2023 | E14: =E13-'Vision patrimoine'!$H$8 -> 38658.73 | F14: =F13-('Vision patrimoine'!$H$9+'Vision patrimoine'!$H$10) -> 30177.18 | H14: =H13-'Vision patrimoine'!$H$11 -> 56011.71 | I14: =I13-'Vision patrimoine'!$H$12 -> 92665.88
C15: Septembre | D15: 2023 | E15: =E14-'Vision patrimoine'!$H$8 -> 38218.55 | F15: =F14-('Vision patrimoine'!$H$9+'Vision patrimoine'!$H$10) -> 29827.18 | H15: =H14-'Vision patrimoine'!$H$11 -> 55579.01 | I15: =I14-'Vision patrimoine'!$H$12 -> 92036.59
C16: Octobre | D16: 2023 | E16: =E15-'Vision patrimoine'!$H$8 -> 37778.37 | F16: =F15-('Vision patrimoine'!$H$9+'Vision patrimoine'!$H$10) -> 29477.18 | H16: =H15-'Vision patrimoine'!$H$11 -> 55146.31 | I16: =I15-'Vision patrimoine'!$H$12 -> 91407.3
C17: Novembre | D17: 2023 | E17: =E16-'Vision patrimoine'!$H$8 -> 37338.19 | F17: =F16-('Vision patrimoine'!$H$9+'Vision patrimoine'!$H$10) -> 29127.18 | H17: =H16-'Vision patrimoine'!$H$11 -> 54713.61 | I17: =I16-'Vision patrimoine'!$H$12 -> 90778.01
C18: Décembre | D18: 2023 | E18: =E17-'Vision patrimoine'!$H$8 -> 36898.01 | F18: =F17-('Vision patrimoine'!$H$9+'Vision patrimoine'!$H$10) -> 28777.18 | H18: =H17-'Vision patrimoine'!$H$11 -> 54280.91 | I18: =I17-'Vision patrimoine'!$H$12 -> 90148.72
C19: Janvier | D19: 2024 | E19: =E18-'Vision patrimoine'!$H$8 -> 36457.83 | F19: =F18-('Vision patrimoine'!$H$9+'Vision patrimoine'!$H$10) -> 28427.18 | H19: =H18-'Vision patrimoine'!$H$11 -> 53848.21 | I19: =I18-'Vision patrimoine'!$H$12 -> 89519.43
C20: Février | D20: 2024 | E20: =E19-'Vision patrimoine'!$H$8 -> 36017.65 | F20: =F19-('Vision patrimoine'!$H$9+'Vision patrimoine'!$H$10) -> 28077.18 | H20: =H19-'Vision patrimoine'!$H$11 -> 53415.51 | I20: =I19-'Vision patrimoine'!$H$12 -> 88890.14
C21: Mars | D21: 2024 | E21: =E20-'Vision patrimoine'!$H$8 -> 35577.47 | F21: =F20-('Vision patrimoine'!$H$9+'Vision patrimoine'!$H$10) -> 27727.18 | H21: =H20-'Vision patrimoine'!$H$11 -> 52982.81 | I21: =I20-'Vision patrimoine'!$H$12 -> 88260.85
C22: Avril | D22: 2024 | E22: =E21-'Vision patrimoine'!$H$8 -> 35137.29 | F22: =F21-('Vision patrimoine'!$H$9+'Vision patrimoine'!$H$10) -> 27377.18 | H22: =H21-'Vision patrimoine'!$H$11 -> 52550.11 | I22: =I21-'Vision patrimoine'!$H$12 -> 87631.56
C23: Mai | D23: 2024 | E23: =E22-'Vision patrimoine'!$H$8 -> 34697.11 | F23: =F22-('Vision patrimoine'!$H$9+'Vision patrimoine'!$H$10) -> 27027.18 | H23: =H22-'Vision patrimoine'!$H$11 -> 52117.41 | I23: =I22-'Vision patrimoine'!$H$12 -> 87002.27
C24: Juin | D24: 2024 | E24: =E23-'Vision patrimoine'!$H$8 -> 34256.93 | F24: =F23-('Vision patrimoine'!$H$9+'Vision patrimoine'!$H$10) -> 26677.18 | H24: =H23-'Vision patrimoine'!$H$11 -> 51684.71 | I24: =I23-'Vision patrimoine'!$H$12 -> 86372.98
C25: Juillet | D25: 2024 | E25: =E24-'Vision patrimoine'!$H$8 -> 33816.75 | F25: =F24-('Vision patrimoine'!$H$9+'Vision patrimoine'!$H$10) -> 26327.18 | H25: =H24-'Vision patrimoine'!$H$11 -> 51252.01 | I25: =I24-'Vision patrimoine'!$H$12 -> 85743.69
... C44: Février | D44: 2026 | E44: =E43-'Vision patrimoine'!$H$8 -> 25453.33 | F44: =F43-('Vision patrimoine'!$H$9+'Vision patrimoine'!$H$10) -> 19677.18 | H44: =H43-'Vision patrimoine'!$H$11 -> 43030.71 | I44: =I43-'Vision patrimoine'!$H$12 -> 73787.18
C45: Mars | D45: 2026 | E45: =E44-'Vision patrimoine'!$H$8 -> 25013.15 | F45: =F44-('Vision patrimoine'!$H$9+'Vision patrimoine'!$H$10) -> 19327.18 | G45: ='Bd liberation Beneduc'!D5 -> 68990 | H45: =H44-'Vision patrimoine'!$H$11 -> 42598.01 | I45: =I44-'Vision patrimoine'!$H$12 -> 73157.89
C46: Avril | D46: 2026 | E46: =E45-'Vision patrimoine'!$H$8 -> 24572.97 | F46: =F45-('Vision patrimoine'!$H$9+'Vision patrimoine'!$H$10) -> 18977.18 | G46: ='Bd liberation Beneduc'!D6 -> 68598.87 | H46: =H45-'Vision patrimoine'!$H$11 -> 42165.31 | I46: =I45-'Vision patrimoine'!$H$12 -> 72528.6
C47: Mai | D47: 2026 | E47: =E46-'Vision patrimoine'!$H$8 -> 24132.79 | F47: =F46-('Vision patrimoine'!$H$9+'Vision patrimoine'!$H$10) -> 18627.18 | G47: ='Bd liberation Beneduc'!D7 -> 68207.74 | H47: =H46-'Vision patrimoine'!$H$11 -> 41732.61 | I47: =I46-'Vision patrimoine'!$H$12 -> 71899.31
C48: Juin | D48: 2026 | E48: =E47-'Vision patrimoine'!$H$8 -> 23692.61 | F48: =F47-('Vision patrimoine'!$H$9+'Vision patrimoine'!$H$10) -> 18277.18 | G48: ='Bd liberation Beneduc'!D8 -> 67814.46 | H48: =H47-'Vision patrimoine'!$H$11 -> 41299.91 | I48: =I47-'Vision patrimoine'!$H$12 -> 71270.02
C49: Juillet | D49: 2026 | E49: =E48-'Vision patrimoine'!$H$8 -> 23252.43 | F49: =F48-('Vision patrimoine'!$H$9+'Vision patrimoine'!$H$10) -> 17927.18 | G49: ='Bd liberation Beneduc'!D9 -> 67420.1 | H49: =H48-'Vision patrimoine'!$H$11 -> 40867.21 | I49: =I48-'Vision patrimoine'!$H$12 -> 70640.73
C50: Août | D50: 2026 | E50: =E49-'Vision patrimoine'!$H$8 -> 22812.25 | F50: =F49-('Vision patrimoine'!$H$9+'Vision patrimoine'!$H$10) -> 17577.18 | G50: ='Bd liberation Beneduc'!D10 -> 67024.66 | H50: =H49-'Vision patrimoine'!$H$11 -> 40434.51 | I50: =I49-'Vision patrimoine'!$H$12 -> 70011.44
C51: Septembre | D51: 2026 | E51: =E50-'Vision patrimoine'!$H$8 -> 22372.07 | F51: =F50-('Vision patrimoine'!$H$9+'Vision patrimoine'!$H$10) -> 17227.18 | G51: ='Bd liberation Beneduc'!D11 -> 66628.13 | H51: =H50-'Vision patrimoine'!$H$11 -> 40001.81 | I51: =I50-'Vision patrimoine'!$H$12 -> 69382.15
C52: Octobre | D52: 2026 | E52: =E51-'Vision patrimoine'!$H$8 -> 21931.89 | F52: =F51-('Vision patrimoine'!$H$9+'Vision patrimoine'!$H$10) -> 16877.18 | G52: ='Bd liberation Beneduc'!D12 -> 66230.51 | H52: =H51-'Vision patrimoine'!$H$11 -> 39569.11 | I52: =I51-'Vision patrimoine'!$H$12 -> 68752.86
C53: Novembre | D53: 2026 | E53: =E52-'Vision patrimoine'!$H$8 -> 21491.71 | F53: =F52-('Vision patrimoine'!$H$9+'Vision patrimoine'!$H$10) -> 16527.18 | G53: ='Bd liberation Beneduc'!D13 -> 65831.79 | H53: =H52-'Vision patrimoine'!$H$11 -> 39136.41 | I53: =I52-'Vision patrimoine'!$H$12 -> 68123.57
C54: Décembre | D54: 2026 | E54: =E53-'Vision patrimoine'!$H$8 -> 21051.53 | F54: =F53-('Vision patrimoine'!$H$9+'Vision patrimoine'!$H$10) -> 16177.18 | G54: ='Bd liberation Beneduc'!D14 -> 65431.98 | H54: =H53-'Vision patrimoine'!$H$11 -> 38703.71 | I54: =I53-'Vision patrimoine'!$H$12 -> 67494.28
C55: Janvier | D55: 2027 | E55: =E54-'Vision patrimoine'!$H$8 -> 20611.35 | F55: =F54-('Vision patrimoine'!$H$9+'Vision patrimoine'!$H$10) -> 15827.18 | G55: ='Bd liberation Beneduc'!D15 -> 65031.07 | H55: =H54-'Vision patrimoine'!$H$11 -> 38271.01 | I55: =I54-'Vision patrimoine'!$H$12 -> 66864.99
C56: Février | D56: 2027 | E56: =E55-'Vision patrimoine'!$H$8 -> 20171.17 | F56: =F55-('Vision patrimoine'!$H$9+'Vision patrimoine'!$H$10) -> 15477.18 | G56: ='Bd liberation Beneduc'!D16 -> 64629.06 | H56: =H55-'Vision patrimoine'!$H$11 -> 37838.31 | I56: =I55-'Vision patrimoine'!$H$12 -> 66235.7
... C102: Décembre | D102: 2030 | E102: =E101-'Vision patrimoine'!$H$8 -> -77.11 | F102: =F101-('Vision patrimoine'!$H$9+'Vision patrimoine'!$H$10) -> -622.82 | G102: ='Bd liberation Beneduc'!D62 -> 44902.08 | H102: =H101-'Vision patrimoine'!$H$11 -> 17934.11 | I102: =I101-'Vision patrimoine'!$H$12 -> 37288.36
C103: Janvier | D103: 2031 | E103: 0 | F103: =F102-('Vision patrimoine'!$H$9+'Vision patrimoine'!$H$10) -> -972.82 | G103: ='Bd liberation Beneduc'!D63 -> 44445.43 | H103: =H102-'Vision patrimoine'!$H$11 -> 17501.41 | I103: =I102-'Vision patrimoine'!$H$12 -> 36659.07
C104: Février | D104: 2031 | E104: 0 | F104: 0 | G104: ='Bd liberation Beneduc'!D64 -> 43987.52 | H104: =H103-'Vision patrimoine'!$H$11 -> 17068.71 | I104: =I103-'Vision patrimoine'!$H$12 -> 36029.78
C105: Mars | D105: 2031 | E105: 0 | F105: 0 | G105: ='Bd liberation Beneduc'!D65 -> 43528.36 | H105: =H104-'Vision patrimoine'!$H$11 -> 16636.01 | I105: =I104-'Vision patrimoine'!$H$12 -> 35400.49
...

Sheet Amort SCI La vista
B2: Amortissement SCI IS LA VISTA
B4: Mois | C4: Année | D4: Maison Mathieu | E4: Capital | F4: 221 Boulevard de la libération | G4: Capital 2
B5: Mai | C5: 2023 | D5: ='Vision patrimoine'!$E$34 -> 95000 | E5: 498.76
B6: Juin | C6: 2023 | D6: =D5-$E6 -> 94498.775 | E6: =E5+2.465 -> 501.225
B7: Juillet | C7: 2023 | D7: =D6-$E7 -> 93995.085 | E7: =E6+2.465 -> 503.69
B8: Août | C8: 2023 | D8: =D7-$E8 -> 93488.93 | E8: =E7+2.465 -> 506.155
B9: Septembre | C9: 2023 | D9: =D8-$E9 -> 92980.31 | E9: =E8+2.465 -> 508.62
B10: Octobre | C10: 2023 | D10: =D9-$E10 -> 92469.225 | E10: =E9+2.465 -> 511.085
B11: Novembre | C11: 2023 | D11: =D10-$E11 -> 91955.675 | E11: =E10+2.465 -> 513.55
B12: Décembre | C12: 2023 | D12: =D11-$E12 -> 91439.66 | E12: =E11+2.465 -> 516.015
B13: Janvier | C13: 2024 | D13: =D12-$E13 -> 90921.18 | E13: =E12+2.465 -> 518.48
B14: Février | C14: 2024 | D14: =D13-$E14 -> 90400.235 | E14: =E13+2.465 -> 520.945
B15: Mars | C15: 2024 | D15: =D14-$E15 -> 89876.825 | E15: =E14+2.465 -> 523.41
B16: Avril | C16: 2024 | D16: =D15-$E16 -> 89350.95 | E16: =E15+2.465 -> 525.875
B17: Mai | C17: 2024 | D17: =D16-$E17 -> 88822.61 | E17: =E16+2.465 -> 528.34
... B26: Février | C26: 2025 | D26: =D25-$E26 -> 83956.625 | E26: =E25+2.465 -> 550.525
B27: Mars | C27: 2025 | D27: =D26-$E27 -> 83403.635 | E27: =E26+2.465 -> 552.99 | F27: ='Vision patrimoine'!E35 -> 90000 | G27: =ROUND(865.685421504164 - H27, 2) -> 528.19 | H27: =ROUND(F27 * 0.00375, 2) -> 337.5 | I27: 51.3 | J27: =ROUND(865.685421504164 + I27, 2) -> 916.99
B28: Avril | C28: 2025 | D28: =D27-$E28 -> 82848.18 | E28: =E27+2.465 -> 555.455 | F28: =F27 - G27 -> 89471.81 | G28: =ROUND(865.685421504164 - H28, 2) -> 530.17 | H28: =ROUND(F28 * 0.00375, 2) -> 335.52 | I28: 51.3 | J28: =ROUND(865.685421504164 + I28, 2) -> 916.99
B29: Mai | C29: 2025 | D29: =D28-$E29 -> 82290.26 | E29: =E28+2.465 -> 557.92 | F29: =F28 - G28 -> 88941.64 | G29: =ROUND(865.685421504164 - H29, 2) -> 532.16 | H29: =ROUND(F29 * 0.00375, 2) -> 333.53 | I29: 51.3 | J29: =ROUND(865.685421504164 + I29, 2) -> 916.99
B30: Juin | C30: 2025 | D30: =D29-$E30 -> 81729.875 | E30: =E29+2.465 -> 560.385 | F30: =F29 - G29 -> 88409.48 | G30: =ROUND(865.685421504164 - H30, 2) -> 534.15 | H30: =ROUND(F30 * 0.00375, 2) -> 331.54 | I30: 51.3 | J30: =ROUND(865.685421504164 + I30, 2) -> 916.99
B31: Juillet | C31: 2025 | D31: =D30-$E31 -> 81167.025 | E31: =E30+2.465 -> 562.85 | F31: =F30 - G30 -> 87875.33 | G31: =ROUND(865.685421504164 - H31, 2) -> 536.16 | H31: =ROUND(F31 * 0.00375, 2) -> 329.53 | I31: 51.3 | J31: =ROUND(865.685421504164 + I31, 2) -> 916.99
B32: Août | C32: 2025 | D32: =D31-$E32 -> 80601.71 | E32: =E31+2.465 -> 565.315 | F32: =F31 - G31 -> 87339.17 | G32: =ROUND(865.685421504164 - H32, 2) -> 538.17 | H32: =ROUND(F32 * 0.00375, 2) -> 327.52 | I32: 51.3 | J32: =ROUND(865.685421504164 + I32, 2) -> 916.99
B33: Septembre | C33: 2025 | D33: =D32-$E33 -> 80033.93 | E33: =E32+2.465 -> 567.78 | F33: =F32 - G32 -> 86801 | G33: =ROUND(865.685421504164 - H33, 2) -> 540.19 | H33: =ROUND(F33 * 0.00375, 2) -> 325.5 | I33: 51.3 | J33: =ROUND(865.685421504164 + I33, 2) -> 916.99
B34: Octobre | C34: 2025 | D34: =D33-$E34 -> 79463.685 | E34: =E33+2.465 -> 570.245 | F34: =F33 - G33 -> 86260.81 | G34: =ROUND(865.685421504164 - H34, 2) -> 542.21 | H34: =ROUND(F34 * 0.00375, 2) -> 323.48 | I34: 51.3 | J34: =ROUND(865.685421504164 + I34, 2) -> 916.99
B35: Novembre | C35: 2025 | D35: =D34-$E35 -> 78890.975 | E35: =E34+2.465 -> 572.71 | F35: =F34 - G34 -> 85718.6 | G35: =ROUND(865.685421504164 - H35, 2) -> 544.25 | H35: =ROUND(F35 * 0.00375, 2) -> 321.44 | I35: 51.3 | J35: =ROUND(865.685421504164 + I35, 2) -> 916.99
B36: Décembre | C36: 2025 | D36: =D35-$E36 -> 78315.8 | E36: =E35+2.465 -> 575.175 | F36: =F35 - G35 -> 85174.35 | G36: =ROUND(865.685421504164 - H36, 2) -> 546.29 | H36: =ROUND(F36 * 0.00375, 2) -> 319.4 | I36: 51.3 | J36: =ROUND(865.685421504164 + I36, 2) -> 916.99
B37: Janvier | C37: 2026 | D37: =D36-$E37 -> 77738.16 | E37: =E36+2.465 -> 577.64 | F37: =F36 - G36 -> 84628.06 | G37: =ROUND(865.685421504164 - H37, 2) -> 548.33 | H37: =ROUND(F37 * 0.00375, 2) -> 317.36 | I37: 51.3 | J37: =ROUND(865.685421504164 + I37, 2) -> 916.99
B38: Février | C38: 2026 | D38: =D37-$E38 -> 77158.055 | E38: =E37+2.465 -> 580.105 | F38: =F37 - G37 -> 84079.73 | G38: =ROUND(865.685421504164 - H38, 2) -> 550.39 | H38: =ROUND(F38 * 0.00375, 2) -> 315.3 | I38: 51.3 | J38: =ROUND(865.685421504164 + I38, 2) -> 916.99
B39: Mars | C39: 2026 | D39: =D38-$E39 -> 76575.485 | E39: =E38+2.465 -> 582.57 | F39: =F38 - G38 -> 83529.34 | G39: =ROUND(865.685421504164 - H39, 2) -> 552.45 | H39: =ROUND(F39 * 0.00375, 2) -> 313.24 | I39: 51.3 | J39: =ROUND(865.685421504164 + I39, 2) -> 916.99
... B148: Avril | C148: 2035 | D148: =D147-$E148 -> -1702.32 | E148: =E147+2.465 -> 851.255 | F148: =F147 - G147 -> 9311.01 | G148: =ROUND(865.685421504164 - H148, 2) -> 830.77 | H148: =ROUND(F148 * 0.00375, 2) -> 34.92 | I148: 51.3 | J148: =ROUND(865.685421504164 + I148, 2) -> 916.99
B149: Mai | C149: 2035 | F149: =F148 - G148 -> 8480.24 | G149: =ROUND(865.685421504164 - H149, 2) -> 833.89 | H149: =ROUND(F149 * 0.00375, 2) -> 31.8 | I149: 51.3 | J149: =ROUND(865.685421504164 + I149, 2) -> 916.99
B150: Juin | C150: 2035 | F150: =F149 - G149 -> 7646.35 | G150: =ROUND(865.685421504164 - H150, 2) -> 837.02 | H150: =ROUND(F150 * 0.00375, 2) -> 28.67 | I150: 51.3 | J150: =ROUND(865.685421504164 + I150, 2) -> 916.99
B151: Juillet | C151: 2035 | F151: =F150 - G150 -> 6809.33 | G151: =ROUND(865.685421504164 - H151, 2) -> 840.16 | H151: =ROUND(F151 * 0.00375, 2) -> 25.53 | I151: 51.3 | J151: =ROUND(865.685421504164 + I151, 2) -> 916.99
B152: Août | C152: 2035 | F152: =F151 - G151 -> 5969.17 | G152: =ROUND(865.685421504164 - H152, 2) -> 843.31 | H152: =ROUND(F152 * 0.00375, 2) -> 22.38 | I152: 51.3 | J152: =ROUND(865.685421504164 + I152, 2) -> 916.99
B153: Septembre | C153: 2035 | F153: =F152 - G152 -> 5125.86 | G153: =ROUND(865.685421504164 - H153, 2) -> 846.47 | H153: =ROUND(F153 * 0.00375, 2) -> 19.22 | I153: 51.3 | J153: =ROUND(865.685421504164 + I153, 2) -> 916.99
B154: Octobre | C154: 2035 | F154: =F153 - G153 -> 4279.39 | G154: =ROUND(865.685421504164 - H154, 2) -> 849.64 | H154: =ROUND(F154 * 0.00375, 2) -> 16.05 | I154: 51.3 | J154: =ROUND(865.685421504164 + I154, 2) -> 916.99
B155: Novembre | C155: 2035 | F155: =F154 - G154 -> 3429.75 | G155: =ROUND(865.685421504164 - H155, 2) -> 852.83 | H155: =ROUND(F155 * 0.00375, 2) -> 12.86 | I155: 51.3 | J155: =ROUND(865.685421504164 + I155, 2) -> 916.99
B156: Décembre | C156: 2035 | F156: =F155 - G155 -> 2576.92 | G156: =ROUND(865.685421504164 - H156, 2) -> 856.03 | H156: =ROUND(F156 * 0.00375, 2) -> 9.66 | I156: 51.3 | J156: =ROUND(865.685421504164 + I156, 2) -> 916.99
B157: Janvier | C157: 2036 | F157: =F156 - G156 -> 1720.89 | G157: =ROUND(865.685421504164 - H157, 2) -> 859.24 | H157: =ROUND(F157 * 0.00375, 2) -> 6.45 | I157: 51.3 | J157: =ROUND(865.685421504164 + I157, 2) -> 916.99
B158: Février | C158: 2036 | F158: =F157 - G157 -> 861.65 | G158: =ROUND(865.685421504164 - H158, 2) -> 862.46 | H158: =ROUND(F158 * 0.00375, 2) -> 3.23 | I158: 51.3 | J158: =ROUND(865.685421504164 + I158, 2) -> 916.99
...

Sheet Amort Libération
B2: Amortissement SCI IS LA VISTA
B4: Mois | C4: Année | D4: Maison Mathieu | E4: Capital
B5: Mai | C5: 2023 | D5: ='Vision patrimoine'!$E$34 -> 95000 | E5: 498.76
B6: Juin | C6: 2023 | D6: =D5-$E6 -> 94498.775 | E6: =E5+2.465 -> 501.225
B7: Juillet | C7: 2023 | D7: =D6-$E7 -> 93995.085 | E7: =E6+2.465 -> 503.69
B8: Août | C8: 2023 | D8: =D7-$E8 -> 93488.93 | E8: =E7+2.465 -> 506.155
B9: Septembre | C9: 2023 | D9: =D8-$E9 -> 92980.31 | E9: =E8+2.465 -> 508.62
B10: Octobre | C10: 2023 | D10: =D9-$E10 -> 92469.225 | E10: =E9+2.465 -> 511.085
B11: Novembre | C11: 2023 | D11: =D10-$E11 -> 91955.675 | E11: =E10+2.465 -> 513.55
B12: Décembre | C12: 2023 | D12: =D11-$E12 -> 91439.66 | E12: =E11+2.465 -> 516.015
B13: Janvier | C13: 2024 | D13: =D12-$E13 -> 90921.18 | E13: =E12+2.465 -> 518.48
B14: Février | C14: 2024 | D14: =D13-$E14 -> 90400.235 | E14: =E13+2.465 -> 520.945
B15: Mars | C15: 2024 | D15: =D14-$E15 -> 89876.825 | E15: =E14+2.465 -> 523.41
B16: Avril | C16: 2024 | D16: =D15-$E16 -> 89350.95 | E16: =E15+2.465 -> 525.875
B17: Mai | C17: 2024 | D17: =D16-$E17 -> 88822.61 | E17: =E16+2.465 -> 528.34
... B148: Avril | C148: 2035 | D148: =D147-$E148 -> -1702.32 | E148: =E147+2.465 -> 851.255

Sheet Amort Troika
B2: Amortissement TROIKA
B4: Mois | C4: Année | D4: 23 RUE ROGER SCHIAFFINI 13003 | E4: 2 RUE DEVILLIERS 13005 | F4: 23 RUE ANTOINE MAILLE 13005 | G4: 13 RUE ROUSSEL DORIA 13004 | H4: 13 RUE ROGER SCHIAFFINI 13003
B5: Novembre | C5: 2022 | D5: ='Vision patrimoine'!$E$22 -> 332569 | E5: ='Vision patrimoine'!#REF! -> #REF! | F5: ='Vision patrimoine'!$E$23 -> 103262.68 | G5: ='Vision patrimoine'!$E$24 -> 76008 | H5: ='Vision patrimoine'!$E$25 -> 41288.94
B6: Décembre | C6: 2022 | D6: =D5-'Vision patrimoine'!$H$22 -> 329258.95 | E6: =E5-'Vision patrimoine'!#REF! -> #REF! | F6: =F5-'Vision patrimoine'!$H$23 -> 102408.13 | G6: =G5-'Vision patrimoine'!$H$24 -> 75480 | H6: =H5-'Vision patrimoine'!$H$25 -> 41001.5
B7: Janvier | C7: 2023 | D7: =D6-'Vision patrimoine'!$H$22 -> 325948.9 | E7: =E6-'Vision patrimoine'!#REF! -> #REF! | F7: =F6-'Vision patrimoine'!$H$23 -> 101553.58 | G7: =G6-'Vision patrimoine'!$H$24 -> 74952 | H7: =H6-'Vision patrimoine'!$H$25 -> 40714.06
B8: Février | C8: 2023 | D8: =D7-'Vision patrimoine'!$H$22 -> 322638.85 | E8: =E7-'Vision patrimoine'!#REF! -> #REF! | F8: =F7-'Vision patrimoine'!$H$23 -> 100699.03 | G8: =G7-'Vision patrimoine'!$H$24 -> 74424 | H8: =H7-'Vision patrimoine'!$H$25 -> 40426.62
B9: Mars | C9: 2023 | D9: =D8-'Vision patrimoine'!$H$22 -> 319328.8 | E9: =E8-'Vision patrimoine'!#REF! -> #REF! | F9: =F8-'Vision patrimoine'!$H$23 -> 99844.48 | G9: =G8-'Vision patrimoine'!$H$24 -> 73896 | H9: =H8-'Vision patrimoine'!$H$25 -> 40139.18
B10: Avril | C10: 2023 | D10: =D9-'Vision patrimoine'!$H$22 -> 316018.75 | E10: =E9-'Vision patrimoine'!#REF! -> #REF! | F10: =F9-'Vision patrimoine'!$H$23 -> 98989.93 | G10: =G9-'Vision patrimoine'!$H$24 -> 73368 | H10: =H9-'Vision patrimoine'!$H$25 -> 39851.74
B11: Mai | C11: 2023 | D11: =D10-'Vision patrimoine'!$H$22 -> 312708.7 | E11: =E10-'Vision patrimoine'!#REF! -> #REF! | F11: =F10-'Vision patrimoine'!$H$23 -> 98135.38 | G11: =G10-'Vision patrimoine'!$H$24 -> 72840 | H11: =H10-'Vision patrimoine'!$H$25 -> 39564.3
B12: Juin | C12: 2023 | D12: =D11-'Vision patrimoine'!$H$22 -> 309398.65 | E12: =E11-'Vision patrimoine'!#REF! -> #REF! | F12: =F11-'Vision patrimoine'!$H$23 -> 97280.83 | G12: =G11-'Vision patrimoine'!$H$24 -> 72312 | H12: =H11-'Vision patrimoine'!$H$25 -> 39276.86
B13: Juillet | C13: 2023 | D13: =D12-'Vision patrimoine'!$H$22 -> 306088.6 | E13: =E12-'Vision patrimoine'!#REF! -> #REF! | F13: =F12-'Vision patrimoine'!$H$23 -> 96426.28 | G13: =G12-'Vision patrimoine'!$H$24 -> 71784 | H13: =H12-'Vision patrimoine'!$H$25 -> 38989.42
B14: Août | C14: 2023 | D14: =D13-'Vision patrimoine'!$H$22 -> 302778.55 | E14: =E13-'Vision patrimoine'!#REF! -> #REF! | F14: =F13-'Vision patrimoine'!$H$23 -> 95571.73 | G14: =G13-'Vision patrimoine'!$H$24 -> 71256 | H14: =H13-'Vision patrimoine'!$H$25 -> 38701.98
B15: Septembre | C15: 2023 | D15: =D14-'Vision patrimoine'!$H$22 -> 299468.5 | E15: =E14-'Vision patrimoine'!#REF! -> #REF! | F15: =F14-'Vision patrimoine'!$H$23 -> 94717.18 | G15: =G14-'Vision patrimoine'!$H$24 -> 70728 | H15: =H14-'Vision patrimoine'!$H$25 -> 38414.54
B16: Octobre | C16: 2023 | D16: =D15-'Vision patrimoine'!$H$22 -> 296158.45 | E16: =E15-'Vision patrimoine'!#REF! -> #REF! | F16: =F15-'Vision patrimoine'!$H$23 -> 93862.63 | G16: =G15-'Vision patrimoine'!$H$24 -> 70200 | H16: =H15-'Vision patrimoine'!$H$25 -> 38127.1
B17: Novembre | C17: 2023 | D17: =D16-'Vision patrimoine'!$H$22 -> 292848.4 | E17: =E16-'Vision patrimoine'!#REF! -> #REF! | F17: =F16-'Vision patrimoine'!$H$23 -> 93008.08 | G17: =G16-'Vision patrimoine'!$H$24 -> 69672 | H17: =H16-'Vision patrimoine'!$H$25 -> 37839.66
... B103: Janvier | C103: 2031 | D103: =D102-'Vision patrimoine'!$H$22 -> 8184.1 | E103: =E102-'Vision patrimoine'!#REF! -> #REF! | F103: =F102-'Vision patrimoine'!$H$23 -> 19516.78 | G103: =G102-'Vision patrimoine'!$H$24 -> 24264 | H103: =H102-'Vision patrimoine'!$H$25 -> 13119.82
B104: Février | C104: 2031 | E104: =E103-'Vision patrimoine'!#REF! -> #REF! | F104: =F103-'Vision patrimoine'!$H$23 -> 18662.23 | G104: =G103-'Vision patrimoine'!$H$24 -> 23736 | H104: =H103-'Vision patrimoine'!$H$25 -> 12832.38
B105: Mars | C105: 2031 | E105: =E104-'Vision patrimoine'!#REF! -> #REF! | F105: =F104-'Vision patrimoine'!$H$23 -> 17807.68 | G105: =G104-'Vision patrimoine'!$H$24 -> 23208 | H105: =H104-'Vision patrimoine'!$H$25 -> 12544.94
B106: Avril | C106: 2031 | E106: =E105-'Vision patrimoine'!#REF! -> #REF! | F106: =F105-'Vision patrimoine'!$H$23 -> 16953.13 | G106: =G105-'Vision patrimoine'!$H$24 -> 22680 | H106: =H105-'Vision patrimoine'!$H$25 -> 12257.5
B107: Mai | C107: 2031 | E107: =E106-'Vision patrimoine'!#REF! -> #REF! | F107: =F106-'Vision patrimoine'!$H$23 -> 16098.58 | G107: =G106-'Vision patrimoine'!$H$24 -> 22152 | H107: =H106-'Vision patrimoine'!$H$25 -> 11970.06
B108: Juin | C108: 2031 | E108: =E107-'Vision patrimoine'!#REF! -> #REF! | F108: =F107-'Vision patrimoine'!$H$23 -> 15244.03 | G108: =G107-'Vision patrimoine'!$H$24 -> 21624 | H108: =H107-'Vision patrimoine'!$H$25 -> 11682.62
B109: Juillet | C109: 2031 | E109: =E108-'Vision patrimoine'!#REF! -> #REF! | F109: =F108-'Vision patrimoine'!$H$23 -> 14389.48 | G109: =G108-'Vision patrimoine'!$H$24 -> 21096 | H109: =H108-'Vision patrimoine'!$H$25 -> 11395.18
B110: Août | C110: 2031 | E110: =E109-'Vision patrimoine'!#REF! -> #REF! | F110: =F109-'Vision patrimoine'!$H$23 -> 13534.93 | G110: =G109-'Vision patrimoine'!$H$24 -> 20568 | H110: =H109-'Vision patrimoine'!$H$25 -> 11107.74
B111: Septembre | C111: 2031 | E111: =E110-'Vision patrimoine'!#REF! -> #REF! | F111: =F110-'Vision patrimoine'!$H$23 -> 12680.38 | G111: =G110-'Vision patrimoine'!$H$24 -> 20040 | H111: =H110-'Vision patrimoine'!$H$25 -> 10820.3
B112: Octobre | C112: 2031 | E112: =E111-'Vision patrimoine'!#REF! -> #REF! | F112: =F111-'Vision patrimoine'!$H$23 -> 11825.83 | G112: =G111-'Vision patrimoine'!$H$24 -> 19512 | H112: =H111-'Vision patrimoine'!$H$25 -> 10532.86
B113: Novembre | C113: 2031 | E113: =E112-'Vision patrimoine'!#REF! -> #REF! | F113: =F112-'Vision patrimoine'!$H$23 -> 10971.28 | G113: =G112-'Vision patrimoine'!$H$24 -> 18984 | H113: =H112-'Vision patrimoine'!$H$25 -> 10245.42
B114: Décembre | C114: 2031 | E114: =E113-'Vision patrimoine'!#REF! -> #REF! | F114: =F113-'Vision patrimoine'!$H$23 -> 10116.73 | G114: =G113-'Vision patrimoine'!$H$24 -> 18456 | H114: =H113-'Vision patrimoine'!$H$25 -> 9957.98
B115: Janvier | C115: 2032 | E115: =E114-'Vision patrimoine'!#REF! -> #REF! | F115: =F114-'Vision patrimoine'!$H$23 -> 9262.18 | G115: =G114-'Vision patrimoine'!$H$24 -> 17928 | H115: =H114-'Vision patrimoine'!$H$25 -> 9670.54
... B121: Juillet | C121: 2032 | E121: =E120-'Vision patrimoine'!#REF! -> #REF! | F121: =F120-'Vision patrimoine'!$H$23 -> 4134.88 | G121: =G120-'Vision patrimoine'!$H$24 -> 14760 | H121: =H120-'Vision patrimoine'!$H$25 -> 7945.9
B122: Août | C122: 2032 | F122: =F121-'Vision patrimoine'!$H$23 -> 3280.33 | G122: =G121-'Vision patrimoine'!$H$24 -> 14232 | H122: =H121-'Vision patrimoine'!$H$25 -> 7658.46
B123: Septembre | C123: 2032 | G123: =G122-'Vision patrimoine'!$H$24 -> 13704 | H123: =H122-'Vision patrimoine'!$H$25 -> 7371.02
B124: Octobre | C124: 2032 | G124: =G123-'Vision patrimoine'!$H$24 -> 13176 | H124: =H123-'Vision patrimoine'!$H$25 -> 7083.58
B125: Novembre | C125: 2032 | G125: =G124-'Vision patrimoine'!$H$24 -> 12648 | H125: =H124-'Vision patrimoine'!$H$25 -> 6796.14
B126: Décembre | C126: 2032 | G126: =G125-'Vision patrimoine'!$H$24 -> 12120 | H126: =H125-'Vision patrimoine'!$H$25 -> 6508.7
B127: Janvier | C127: 2033 | G127: =G126-'Vision patrimoine'!$H$24 -> 11592 | H127: =H126-'Vision patrimoine'!$H$25 -> 6221.26
B128: Février | C128: 2033 | G128: =G127-'Vision patrimoine'!$H$24 -> 11064 | H128: =H127-'Vision patrimoine'!$H$25 -> 5933.82
B129: Mars | C129: 2033 | G129: =G128-'Vision patrimoine'!$H$24 -> 10536 | H129: =H128-'Vision patrimoine'!$H$25 -> 5646.38
B130: Avril | C130: 2033 | G130: =G129-'Vision patrimoine'!$H$24 -> 10008 | H130: =H129-'Vision patrimoine'!$H$25 -> 5358.94
B131: Mai | C131: 2033 | G131: =G130-'Vision patrimoine'!$H$24 -> 9480 | H131: =H130-'Vision patrimoine'!$H$25 -> 5071.5
B132: Juin | C132: 2033 | G132: =G131-'Vision patrimoine'!$H$24 -> 8952 | H132: =H131-'Vision patrimoine'!$H$25 -> 4784.06
...

Sheet Residence Principale
B2: Amortissement résidence principale
B4: Mois | C4: Année | D4: 33 chemin du petit pin vert | E4: Capital déduit | F4: Mensualité hors assurance (€) | G4: Intérêts (€) | H4: Autres frais inclus
B5: Novembre | C5: 2024 | D5: 266771.42 | E5: =F5-G5 -> 4.1 | F5: 840 | G5: 835.9 | H5: 65.7
B6: Décembre | C6: 2024 | D6: =D5-E6 -> 266767.3 | E6: =F6-G6 -> 4.12 | F6: 840 | G6: 835.88 | H6: 64.48
B7: Janvier | C7: 2025 | D7: =D6-E7 -> 266763.17 | E7: =F7-G7 -> 4.13 | F7: 840 | G7: 835.87 | H7: 64.48
B8: Février | C8: 2025 | D8: =D7-E8 -> 266759.03 | E8: =F8-G8 -> 4.14 | F8: 840 | G8: 835.86 | H8: 64.48
B9: Mars | C9: 2025 | D9: =D8-E9 -> 266754.87 | E9: =F9-G9 -> 4.16 | F9: 840 | G9: 835.84 | H9: 64.48
B10: Avril | C10: 2025 | D10: =D9-E10 -> 266750.7 | E10: =F10-G10 -> 4.17 | F10: 840 | G10: 835.83 | H10: 64.48
B11: Mai | C11: 2025 | D11: =D10-E11 -> 266746.52 | E11: =F11-G11 -> 4.18 | F11: 840 | G11: 835.82 | H11: 64.48
B12: Juin | C12: 2025 | D12: =D11-E12 -> 266742.33 | E12: =F12-G12 -> 4.19 | F12: 840 | G12: 835.81 | H12: 64.48
B13: Juillet | C13: 2025 | D13: =D12-E13 -> 266738.12 | E13: =F13-G13 -> 4.21 | F13: 840 | G13: 835.79 | H13: 64.48
B14: Août | C14: 2025 | D14: =D13-E14 -> 266733.9 | E14: =F14-G14 -> 4.22 | F14: 840 | G14: 835.78 | H14: 64.48
B15: Septembre | C15: 2025 | D15: =D14-E15 -> 266729.67 | E15: =F15-G15 -> 4.23 | F15: 840 | G15: 835.77 | H15: 64.48
B16: Octobre | C16: 2025 | D16: =D15-E16 -> 266725.42 | E16: =F16-G16 -> 4.25 | F16: 840 | G16: 835.75 | H16: 64.48
B17: Novembre | C17: 2025 | D17: =D16-E17 -> 266721.16 | E17: =F17-G17 -> 4.26 | F17: 840 | G17: 835.74 | H17: 64.48
... B184: Octobre | C184: 2039 | D184: =D183-E184 -> 1048.18 | E184: =F184-G184 -> 2107.01 | F184: 2116.9 | G184: 9.89 | H184: 64.48
B185: Novembre | C185: 2039 | D185: 0 | E185: =F185-G185 -> 2113.62 | F185: 2116.9 | G185: 3.28 | H185: 64.48
B186: Décembre | C186: 2039 | D186: 0 | E186: =F186-G186 -> 2116.9 | F186: 2116.9 | G186: 0 | H186: 64.48
B187: Janvier | C187: 2040 | D187: 0 | E187: =F187-G187 -> 2116.9 | F187: 2116.9 | G187: 0 | H187: 64.48
B188: Février | C188: 2040 | D188: 0 | E188: =F188-G188 -> 2116.9 | F188: 2116.9 | G188: 0 | H188: 64.48
B189: Mars | C189: 2040 | D189: 0 | E189: =F189-G189 -> 2116.9 | F189: 2116.9 | G189: 0 | H189: 64.48
B190: Avril | C190: 2040 | D190: 0 | E190: =F190-G190 -> 2116.9 | F190: 2116.9 | G190: 0 | H190: 64.48
B191: Mai | C191: 2040 | D191: 0 | E191: =F191-G191 -> 2116.9 | F191: 2116.9 | G191: 0 | H191: 64.48
B192: Juin | C192: 2040 | D192: 0 | E192: =F192-G192 -> 2116.9 | F192: 2116.9 | G192: 0 | H192: 64.48
B193: Juillet | C193: 2040 | D193: 0 | E193: =F193-G193 -> 2116.9 | F193: 2116.9 | G193: 0 | H193: 64.48
B194: Août | C194: 2040 | D194: 0 | E194: =F194-G194 -> 2116.9 | F194: 2116.9 | G194: 0 | H194: 64.48
B195: Septembre | C195: 2040 | D195: 0 | E195: =F195-G195 -> 2116.9 | F195: 2116.9 | G195: 0 | H195: 64.48
B196: Octobre | C196: 2040 | D196: 0 | E196: =F196-G196 -> 2116.9 | F196: 2116.9 | G196: 0 | H196: 64.48
... B304: Octobre | C304: 2049 | D304: 0 | E304: =F304-G304 -> 2116.9 | F304: 2116.9 | G304: 0 | H304: 64.48

Sheet Bd liberation Beneduc
B2: Amortissement résidence principale
B4: Mois | C4: Année | D4: 221 Bd libération | E4: Capital amorti | F4: Intérêts (€) | G4: Assurance groupe prélevée par le prêteur | H4: Echeance (ass. Groupe prélevée par le prêteur* incluse)
B5: Mars | C5: 2026 | D5: 68990 | E5: =391.13 -> 391.13 | F5: =18.71 -> 18.71 | G5: =0.93 -> 0.93 | H5: 410.77 | I5: taux annuel | J5: 0.033
B6: Mars | C6: 2026 | D6: =D5-E5 -> 68598.87 | E6: =H5-G5-F5 -> 391.13 | F6: =ROUND(D6*J$5/12,2) -> 188.65 | G6: =9.43 -> 9.43 | H6: 590.28 | I6: taux mensuel | J6: =3.3%/12 -> 0.00275
B7: Avril | C7: 2026 | D7: =D6-E6 -> 68207.74 | E7: =H6-G6-F6 -> 392.2 | F7: =ROUND(D7*J$5/12,2) -> 187.57 | G7: =9.43 -> 9.43 | H7: 590.28 | I7: mensualité normal assurance incluse | J7: 410.77
B8: Mai | C8: 2026 | D8: =D7-E8 -> 67814.46 | E8: =H7-G7-F7 -> 393.28 | F8: =ROUND(D8*J$5/12,2) -> 186.49 | G8: =9.43 -> 9.43 | H8: 590.28
B9: Juin | C9: 2026 | D9: =D8-E9 -> 67420.1 | E9: =H8-G8-F8 -> 394.36 | F9: =ROUND(D9*J$5/12,2) -> 185.41 | G9: =9.43 -> 9.43 | H9: 590.28
B10: Juillet | C10: 2026 | D10: =D9-E10 -> 67024.66 | E10: =H9-G9-F9 -> 395.44 | F10: =ROUND(D10*J$5/12,2) -> 184.32 | G10: =9.43 -> 9.43 | H10: 590.28
B11: Août | C11: 2026 | D11: =D10-E11 -> 66628.13 | E11: =H10-G10-F10 -> 396.53 | F11: =ROUND(D11*J$5/12,2) -> 183.23 | G11: =9.43 -> 9.43 | H11: 590.28
B12: Septembre | C12: 2026 | D12: =D11-E12 -> 66230.51 | E12: =H11-G11-F11 -> 397.62 | F12: =ROUND(D12*J$5/12,2) -> 182.13 | G12: =9.43 -> 9.43 | H12: 590.28
B13: Octobre | C13: 2026 | D13: =D12-E13 -> 65831.79 | E13: =H12-G12-F12 -> 398.72 | F13: =ROUND(D13*J$5/12,2) -> 181.04 | G13: =9.43 -> 9.43 | H13: 590.28
B14: Novembre | C14: 2026 | D14: =D13-E14 -> 65431.98 | E14: =H13-G13-F13 -> 399.81 | F14: =ROUND(D14*J$5/12,2) -> 179.94 | G14: =9.43 -> 9.43 | H14: 590.28
B15: Décembre | C15: 2027 | D15: =D14-E15 -> 65031.07 | E15: =H14-G14-F14 -> 400.91 | F15: =ROUND(D15*J$5/12,2) -> 178.84 | G15: =9.43 -> 9.43 | H15: 590.28
B16: Janvier | C16: 2027 | D16: =D15-E16 -> 64629.06 | E16: =H15-G15-F15 -> 402.01 | F16: =ROUND(D16*J$5/12,2) -> 177.73 | G16: =9.43 -> 9.43 | H16: 590.28
B17: Février | C17: 2027 | D17: =D16-E17 -> 64225.94 | E17: =H16-G16-F16 -> 403.12 | F17: =ROUND(D17*J$5/12,2) -> 176.62 | G17: =9.43 -> 9.43 | H17: 590.28
B18: Mars | C18: 2027 | D18: =D17-E18 -> 63821.71 | E18: =H17-G17-F17 -> 404.23 | F18: =ROUND(D18*J$5/12,2) -> 175.51 | G18: =9.43 -> 9.43 | H18: 590.28
B19: Avril | C19: 2027 | D19: =D18-E19 -> 63416.37 | E19: =H18-G18-F18 -> 405.34 | F19: =ROUND(D19*J$5/12,2) -> 174.4 | G19: =9.43 -> 9.43 | H19: 590.28
... B148: Janvier | C148: 2038 | D148: =D147-E148 -> 973.02 | E148: =H147-G147-F147 -> 568.82 | F148: =ROUND(D148*J$5/12,2) -> 2.68 | G148: =9.43 -> 9.43 | H148: 582.97
B149: Février
